An exception occurred during task execution. To see the full traceback, use -vvv. The error was: apt_pkg.Error: E:Malformed entry 1 in list file /etc/apt/sources.list.d/nodesource-repo.list (Component), E:The list of sources could not be read.
fatal: [Ubuntu 22.04]: FAILED! => {"changed": false, "module_stderr": "Traceback (most recent call last):\n  File \"/home/domenickd3/.ansible/tmp/ansible-tmp-1696741993.6961412-5553-224868664009966/AnsiballZ_apt_repository.py\", line 107, in <module>\n    _ansiballz_main()\n  File \"/home/domenickd3/.ansible/tmp/ansible-tmp-1696741993.6961412-5553-224868664009966/AnsiballZ_apt_repository.py\", line 99, in _ansiballz_main\n    invoke_module(zipped_mod, temp_path, ANSIBALLZ_PARAMS)\n  File \"/home/domenickd3/.ansible/tmp/ansible-tmp-1696741993.6961412-5553-224868664009966/AnsiballZ_apt_repository.py\", line 47, in invoke_module\n    runpy.run_module(mod_name='ansible.modules.apt_repository', init_globals=dict(_module_fqn='ansible.modules.apt_repository', _modlib_path=modlib_path),\n  File \"/usr/lib/python3.10/runpy.py\", line 224, in run_module\n    return _run_module_code(code, init_globals, run_name, mod_spec)\n  File \"/usr/lib/python3.10/runpy.py\", line 96, in _run_module_code\n    _run_code(code, mod_globals, init_globals,\n  File \"/usr/lib/python3.10/runpy.py\", line 86, in _run_code\n    exec(code, run_globals)\n  File \"/tmp/ansible_ansible.builtin.apt_repository_payload_kf_nwrp4/ansible_ansible.builtin.apt_repository_payload.zip/ansible/modules/apt_repository.py\", line 765, in <module>\n  File \"/tmp/ansible_ansible.builtin.apt_repository_payload_kf_nwrp4/ansible_ansible.builtin.apt_repository_payload.zip/ansible/modules/apt_repository.py\", line 742, in main\n  File \"/usr/lib/python3/dist-packages/apt/cache.py\", line 152, in __init__\n    self.open(progress)\n  File \"/usr/lib/python3/dist-packages/apt/cache.py\", line 214, in open\n    self._cache = apt_pkg.Cache(progress)\napt_pkg.Error: E:Malformed entry 1 in list file /etc/apt/sources.list.d/nodesource-repo.list (Component), E:The list of sources could not be read.\n", "module_stdout": "", "msg": "MODULE FAILURE\nSee stdout/stderr for the exact error", "rc": 1}
